Workbook

Sheet Customer Names
A1: Customer ID | B1: name | C1: Title Name | D1: First Name | E1: Last Name
A2: Id1 | B2: Hawks, Ms. Kelly | C2: =TRIM(MID( B2,FIND(",", B2)+1,FIND(".", B2)-FIND(",", B2))) -> Ms. | D2: =TRIM(RIGHT(B2,LEN(B2)-FIND(".",B2))) -> Kelly | E2: =LEFT(B2,FIND(",",B2)-1) -> Hawks
A3: Id2 | B3: Lehner, Mr. Matthew D | C3: =TRIM(MID( B3,FIND(",", B3)+1,FIND(".", B3)-FIND(",", B3))) -> Mr. | D3: =TRIM(RIGHT(B3,LEN(B3)-FIND(".",B3))) -> Matthew D | E3: =LEFT(B3,FIND(",",B3)-1) -> Lehner
A4: Id3 | B4: Lu, Mr. Phil | C4: =TRIM(MID( B4,FIND(",", B4)+1,FIND(".", B4)-FIND(",", B4))) -> Mr. | D4: =TRIM(RIGHT(B4,LEN(B4)-FIND(".",B4))) -> Phil | E4: =LEFT(B4,FIND(",",B4)-1) -> Lu
A5: Id4 | B5: Osborne, Ms. Kelsey | C5: =TRIM(MID( B5,FIND(",", B5)+1,FIND(".", B5)-FIND(",", B5))) -> Ms. | D5: =TRIM(RIGHT(B5,LEN(B5)-FIND(".",B5))) -> Kelsey | E5: =LEFT(B5,FIND(",",B5)-1) -> Osborne
A6: Id5 | B6: Kadala, Ms. Kristyn | C6: =TRIM(MID( B6,FIND(",", B6)+1,FIND(".", B6)-FIND(",", B6))) -> Ms. | D6: =TRIM(RIGHT(B6,LEN(B6)-FIND(".",B6))) -> Kristyn | E6: =LEFT(B6,FIND(",",B6)-1) -> Kadala
A7: Id6 | B7: Baker, Mr. Russell B. | C7: =TRIM(MID( B7,FIND(",", B7)+1,FIND(".", B7)-FIND(",", B7))) -> Mr. | D7: =TRIM(RIGHT(B7,LEN(B7)-FIND(".",B7))) -> Russell B. | E7: =LEFT(B7,FIND(",",B7)-1) -> Baker
A8: Id7 | B8: Macpherson, Mr. Scott | C8: =TRIM(MID( B8,FIND(",", B8)+1,FIND(".", B8)-FIND(",", B8))) -> Mr. | D8: =TRIM(RIGHT(B8,LEN(B8)-FIND(".",B8))) -> Scott | E8: =LEFT(B8,FIND(",",B8)-1) -> Macpherson
A9: Id8 | B9: Hallman, Mr. Stephen | C9: =TRIM(MID( B9,FIND(",", B9)+1,FIND(".", B9)-FIND(",", B9))) -> Mr. | D9: =TRIM(RIGHT(B9,LEN(B9)-FIND(".",B9))) -> Stephen | E9: =LEFT(B9,FIND(",",B9)-1) -> Hallman
A10: Id9 | B10: Moran, Mr. Patrick R. | C10: =TRIM(MID( B10,FIND(",", B10)+1,FIND(".", B10)-FIND(",", B10))) -> Mr. | D10: =TRIM(RIGHT(B10,LEN(B10)-FIND(".",B10))) -> Patrick R. | E10: =LEFT(B10,FIND(",",B10)-1) -> Moran
A11: Id10 | B11: Benner, Ms. Brooke N. | C11: =TRIM(MID( B11,FIND(",", B11)+1,FIND(".", B11)-FIND(",", B11))) -> Ms. | D11: =TRIM(RIGHT(B11,LEN(B11)-FIND(".",B11))) -> Brooke N. | E11: =LEFT(B11,FIND(",",B11)-1) -> Benner
A12: Id11 | B12: Fierro Vargas, Ms. Paola Andrea | C12: =TRIM(MID( B12,FIND(",", B12)+1,FIND(".", B12)-FIND(",", B12))) -> Ms. | D12: =TRIM(RIGHT(B12,LEN(B12)-FIND(".",B12))) -> Paola Andrea | E12: =LEFT(B12,FIND(",",B12)-1) -> Fierro Vargas
A13: Id12 | B13: Franz, Mr. David | C13: =TRIM(MID( B13,FIND(",", B13)+1,FIND(".", B13)-FIND(",", B13))) -> Mr. | D13: =TRIM(RIGHT(B13,LEN(B13)-FIND(".",B13))) -> David | E13: =LEFT(B13,FIND(",",B13)-1) -> Franz
... A2336: Id2335 | B2336: German, Mr. Aaron K | C2336: =TRIM(MID( B2336,FIND(",", B2336)+1,FIND(".", B2336)-FIND(",", B2336))) -> Mr. | D2336: =TRIM(RIGHT(B2336,LEN(B2336)-FIND(".",B2336))) -> Aaron K | E2336: =LEFT(B2336,FIND(",",B2336)-1) -> German

Sheet Medical Examinations
A1: Customer ID | B1: BMI | C1: HBA1C | D1: Heart Issues | E1: Any Transplants | F1: Cancer history | G1: NumberOfMajorSurgeries | H1: smoker
A2: Id1 | B2: 47.41 | C2: 7.47 | D2: No | E2: No | F2: No | G2: No major surgery | H2: yes | J2: columns | K2: missing values | L2: Columns with "?"
A3: Id2 | B3: 30.36 | C3: 5.77 | D3: No | E3: No | F3: No | G3: No major surgery | H3: yes | J3: customer id | K3: =COUNTBLANK(A2:A2336) -> 0 | L3: =COUNTIF(A1:A2336,"?") -> 0
A4: Id3 | B4: 34.485 | C4: 11.87 | D4: yes | E4: No | F4: No | G4: 2 | H4: yes | J4: BMI | K4: =COUNTBLANK(B2:B2336) -> 0 | L4: =COUNTIF(B2:B2336,"?") -> 0
A5: Id4 | B5: 38.095 | C5: 6.05 | D5: No | E5: No | F5: No | G5: No major surgery | H5: yes | J5: HBA1C | K5: =COUNTBLANK(C2:C2336) -> 0 | L5: =COUNTIF(C2:C2336,"?") -> 0
A6: Id5 | B6: 35.53 | C6: 5.45 | D6: No | E6: No | F6: No | G6: No major surgery | H6: yes | J6: Heart issues | K6: =COUNTBLANK(D2:D2336) -> 0 | L6: =COUNTIF(D2:D2336,"?") -> 0
A7: Id6 | B7: 32.8 | C7: 6.59 | D7: No | E7: No | F7: No | G7: No major surgery | H7: yes | J7: Cancer history | K7: =COUNTBLANK(F2:F2336) -> 0 | L7: =COUNTIF(F2:F2336,"?") -> 0
A8: Id7 | B8: 36.4 | C8: 6.07 | D8: No | E8: No | F8: No | G8: No major surgery | H8: yes | J8: NumberOfMajorSurgeries | K8: =COUNTBLANK(G2336) -> 0 | L8: =COUNTIF(G2:G2336,"?") -> 0
A9: Id8 | B9: 36.96 | C9: 7.93 | D9: No | E9: No | F9: No | G9: 3 | H9: yes | J9: smoker | K9: =COUNTBLANK(H2336) -> 0 | L9: =COUNTIF(H2:H2336,"?") -> 2
A10: Id9 | B10: 41.14 | C10: 9.58 | D10: yes | E10: No | F10: Yes | G10: 1 | H10: yes
A11: Id10 | B11: 38.06 | C11: 10.79 | D11: No | E11: No | F11: No | G11: No major surgery | H11: yes
A12: Id11 | B12: 37.7 | C12: 5.96 | D12: yes | E12: No | F12: No | G12: 2 | H12: yes
A13: Id12 | B13: 42.13 | C13: 11.9 | D13: No | E13: No | F13: No | G13: No major surgery | H13: yes
A14: Id13 | B14: 40.92 | C14: 8.41 | D14: No | E14: No | F14: No | G14: No major surgery | H14: yes
A15: Id14 | B15: 40.565 | C15: 7.02 | D15: No | E15: No | F15: No | G15: No major surgery | H15: yes
A16: Id15 | B16: 36.385 | C16: 7.59 | D16: yes | E16: No | F16: No | G16: 2 | H16: yes
A17: Id16 | B17: 39.9 | C17: 11.32 | D17: No | E17: No | F17: No | G17: No major surgery | H17: yes
A18: Id17 | B18: 33.8 | C18: 7.67 | D18: No | E18: No | F18: No | G18: 3 | H18: yes
A19: Id18 | B19: 36.765 | C19: 7.29 | D19: yes | E19: No | F19: Yes | G19: 1 | H19: yes
A20: Id19 | B20: 36.955 | C20: 4.72 | D20: yes | E20: No | F20: No | G20: 1 | H20: yes
A21: Id20 | B21: 42.9 | C21: 11.41 | D21: No | E21: No | F21: No | G21: No major surgery | H21: yes
A22: Id21 | B22: 36.3 | C22: 11.5 | D22: yes | E22: No | F22: No | G22: 2 | H22: yes
A23: Id22 | B23: 32.2 | C23: 6.22 | D23: yes | E23: No | F23: No | G23: 2 | H23: yes
A24: Id23 | B24: 31.3 | C24: 11.38 | D24: No | E24: No | F24: No | G24: 3 | H24: yes
A25: Id24 | B25: 41.8 | C25: 7.89 | D25: yes | E25: No | F25: No | G25: 2 | H25: yes
A26: Id25 | B26: 35.09 | C26: 4.38 | D26: yes | E26: No | F26: No | G26: 2 | H26: yes
A27: Id26 | B27: 33.88 | C27: 7.01 | D27: No | E27: No | F27: No | G27: 3 | H27: yes
A28: Id27 | B28: 30.875 | C28: 11.88 | D28: No | E28: No | F28: No | G28: No major surgery | H28: yes
A29: Id28 | B29: 36.86 | C29: 5.19 | D29: yes | E29: No | F29: Yes | G29: 1 | H29: yes
A30: Id29 | B30: 35.86 | C30: 6.74 | D30: yes | E30: No | F30: No | G30: 2 | H30: yes
A31: Id30 | B31: 37.05 | C31: 8.44 | D31: No | E31: No | F31: No | G31: No major surgery | H31: yes
A32: Id31 | B32: 43.89 | C32: 8.71 | D32: No | E32: No | F32: No | G32: No major surgery | H32: yes
A33: Id32 | B33: 42.35 | C33: 5.08 | D33: yes | E33: No | F33: No | G33: No major surgery | H33: yes
A34: Id33 | B34: 31.35 | C34: 6.86 | D34: No | E34: No | F34: No | G34: No major surgery | H34: yes
A35: Id34 | B35: 47.6 | C35: 5.95 | D35: yes | E35: No | F35: No | G35: No major surgery | H35: yes
A36: Id35 | B36: 46.2 | C36: 6.09 | D36: No | E36: No | F36: Yes | G36: 1 | H36: yes
A37: Id36 | B37: 32.015 | C37: 11.75 | D37: No | E37: No | F37: No | G37: No major surgery | H37: yes
A38: Id37 | B38: 40.565 | C38: 7.37 | D38: No | E38: No | F38: No | G38: No major surgery | H38: yes
A39: Id38 | B39: 32.45 | C39: 11.91 | D39: No | E39: No | F39: No | G39: No major surgery | H39: yes
A40: Id39 | B40: 34.96 | C40: 6.52 | D40: No | E40: No | F40: No | G40: No major surgery | H40: yes
...

Sheet Hospitalisation Details
A1: Customer ID | B1: year | C1: month | D1: date | E1: children | F1: charges | G1: Hospital tier | H1: City tier | I1: State ID
A2: Id2335 | B2: 1992 | C2: Jul | D2: 9 | E2: 0 | F2: 563.84 | G2: tier - 2 | H2: tier - 3 | I2: R1013 | K2: columns | L2: missing values | M2: columns with "?"
A3: Id2334 | B3: 1992 | C3: Nov | D3: 30 | E3: 0 | F3: 570.62 | G3: tier - 2 | H3: tier - 1 | I3: R1013 | K3: customer id | L3: =COUNTBLANK(A2:A2344) -> 0 | M3: =COUNTIF(A2:A2344,"?") -> 6
A4: Id2333 | B4: 1993 | C4: Jun | D4: 30 | E4: 0 | F4: 600 | G4: tier - 2 | H4: tier - 1 | I4: R1013 | K4: year | L4: =COUNTBLANK(B2:B2344) -> 0 | M4: =COUNTIF(B2:B2344,"?") -> 2
A5: Id2332 | B5: 1992 | C5: Sep | D5: 13 | E5: 0 | F5: 604.54 | G5: tier - 3 | H5: tier - 3 | I5: R1013 | K5: month | L5: =COUNTBLANK(C2:C2344) -> 0 | M5: =COUNTIF(C2:C2344,"?") -> 3
A6: Id2331 | B6: 1998 | C6: Jul | D6: 27 | E6: 0 | F6: 637.26 | G6: tier - 3 | H6: tier - 3 | I6: R1013 | K6: date | L6: =COUNTBLANK(D2:D2344) -> 0 | M6: =COUNTIF(D2:D2344,"?") -> 0
A7: Id2330 | B7: 2001 | C7: Nov | D7: 20 | E7: 0 | F7: 646.14 | G7: tier - 3 | H7: tier - 3 | I7: R1012 | K7: children | L7: =COUNTBLANK(E2:E2344) -> 0 | M7: =COUNTIF(E2:E2344,"?") -> 0
A8: Id2329 | B8: 1993 | C8: Jun | D8: 1 | E8: 0 | F8: 650 | G8: tier - 3 | H8: tier - 3 | I8: R1013 | K8: charges | L8: =COUNTBLANK(F2:F2344) -> 0 | M8: =COUNTIF(F2:F2344,"?") -> 0
A9: Id2328 | B9: 1995 | C9: Jul | D9: 4 | E9: 0 | F9: 650 | G9: tier - 3 | H9: tier - 3 | I9: R1013 | K9: hospital tier | L9: =COUNTBLANK(G2:G2344) -> 0 | M9: =COUNTIF(G2:G2344,"?") -> 1
A10: Id2327 | B10: 2002 | C10: Nov | D10: 29 | E10: 0 | F10: 668 | G10: tier - 3 | H10: tier - 2 | I10: R1012 | K10: city tier | L10: =COUNTBLANK(H2:H2344) -> 0 | M10: =COUNTIF(H2:H2344,"?") -> 1
A11: Id2326 | B11: 1997 | C11: Nov | D11: 9 | E11: 0 | F11: 670 | G11: tier - 3 | H11: tier - 3 | I11: R1013 | K11: state id | L11: =COUNTBLANK(I2:I2344) -> 0 | M11: =COUNTIF(I2:I2344,"?") -> 2
A12: Id2325 | B12: 2001 | C12: Sep | D12: 12 | E12: 0 | F12: 687.54 | G12: tier - 3 | H12: tier - 2 | I12: R1013
A13: Id2324 | B13: 1999 | C13: Dec | D13: 26 | E13: 0 | F13: 700 | G13: ? | H13: tier - 3 | I13: R1013
A14: Id2323 | B14: 1999 | C14: Dec | D14: 14 | E14: 0 | F14: 722.99 | G14: tier - 3 | H14: tier - 1 | I14: R1013
A15: Id2322 | B15: 2002 | C15: ? | D15: 19 | E15: 0 | F15: 750 | G15: tier - 3 | H15: tier - 1 | I15: R1012
A16: Id2321 | B16: 1993 | C16: Aug | D16: 9 | E16: 0 | F16: 760 | G16: tier - 3 | H16: tier - 1 | I16: R1013
A17: Id2320 | B17: 1996 | C17: Oct | D17: 22 | E17: 0 | F17: 760 | G17: tier - 3 | H17: tier - 3 | I17: R1013
A18: Id2319 | B18: 1993 | C18: Jun | D18: 28 | E18: 0 | F18: 770 | G18: tier - 3 | H18: tier - 3 | I18: R1013
A19: Id2318 | B19: 1996 | C19: ? | D19: 18 | E19: 0 | F19: 770.38 | G19: tier - 3 | H19: ? | I19: R1012
A20: Id2317 | B20: 1995 | C20: Dec | D20: 7 | E20: 0 | F20: 773.54 | G20: tier - 3 | H20: tier - 2 | I20: R1013
A21: Id2316 | B21: 2004 | C21: Oct | D21: 7 | E21: 0 | F21: 830.52 | G21: tier - 3 | H21: tier - 2 | I21: R1011
A22: Id2315 | B22: 2000 | C22: Nov | D22: 18 | E22: 0 | F22: 865.41 | G22: tier - 3 | H22: tier - 1 | I22: R1013
A23: Id2314 | B23: 1993 | C23: Nov | D23: 27 | E23: 0 | F23: 896.21 | G23: tier - 3 | H23: tier - 1 | I23: R1013
... A1050: Id1290 | B1050: 1977 | C1050: Jul | D1050: 26 | E1050: 2 | F1050: 8527.53 | G1050: tier - 2 | H1050: tier - 2 | I1050: R1013
A1051: Id1289 | B1051: ? | C1051: Jul | D1051: 24 | E1051: 0 | F1051: 8534.67 | G1051: tier - 2 | H1051: tier - 3 | I1051: R1024
A1052: Id1288 | B1052: 1981 | C1052: Dec | D1052: 27 | E1052: 3 | F1052: 8538.29 | G1052: tier - 2 | H1052: tier - 3 | I1052: R1024
A1053: Id1287 | B1053: 1975 | C1053: Nov | D1053: 6 | E1053: 1 | F1053: 8539.67 | G1053: tier - 2 | H1053: tier - 3 | I1053: R1011
A1054: Id1286 | B1054: ? | C1054: Dec | D1054: 12 | E1054: 1 | F1054: 8547.69 | G1054: tier - 2 | H1054: tier - 1 | I1054: R1013
A1055: Id1285 | B1055: 1975 | C1055: Aug | D1055: 6 | E1055: 1 | F1055: 8551.35 | G1055: tier - 2 | H1055: tier - 2 | I1055: R1011
A1056: Id1284 | B1056: 1975 | C1056: Aug | D1056: 21 | E1056: 1 | F1056: 8556.91 | G1056: tier - 2 | H1056: tier - 1 | I1056: R1011
A1057: Id1283 | B1057: 1988 | C1057: Sep | D1057: 21 | E1057: 3 | F1057: 8567.25 | G1057: tier - 2 | H1057: tier - 1 | I1057: R1012
A1058: Id1282 | B1058: 1975 | C1058: Sep | D1058: 26 | E1058: 1 | F1058: 8569.86 | G1058: tier - 2 | H1058: tier - 3 | I1058: R1013
A1059: Id1281 | B1059: 1982 | C1059: Dec | D1059: 6 | E1059: 3 | F1059: 8572.04 | G1059: tier - 2 | H1059: tier - 2 | I1059: R1021
A1060: Id1280 | B1060: 1987 | C1060: Nov | D1060: 11 | E1060: 3 | F1060: 8573.3 | G1060: tier - 2 | H1060: tier - 2 | I1060: R1021
A1061: Id1279 | B1061: 1983 | C1061: Dec | D1061: 30 | E1061: 5 | F1061: 8582.3 | G1061: tier - 2 | H1061: tier - 1 | I1061: R1013
A1062: Id1278 | B1062: 1983 | C1062: Jul | D1062: 25 | E1062: 5 | F1062: 8596.83 | G1062: tier - 2 | H1062: tier - 3 | I1062: R1013
A1063: Id1277 | B1063: 1973 | C1063: Jul | D1063: 11 | E1063: 0 | F1063: 8601.33 | G1063: tier - 2 | H1063: tier - 1 | I1063: R1013
A1064: Id1276 | B1064: 1977 | C1064: Sep | D1064: 24 | E1064: 2 | F1064: 8603.82 | G1064: tier - 2 | H1064: tier - 1 | I1064: R1019
A1065: Id1275 | B1065: 1977 | C1065: Nov | D1065: 12 | E1065: 2 | F1065: 8604.48 | G1065: tier - 3 | H1065: tier - 2 | I1065: R1016
A1066: Id1274 | B1066: 1977 | C1066: Oct | D1066: 15 | E1066: 3 | F1066: 8605.36 | G1066: tier - 2 | H1066: tier - 2 | I1066: R1013
...

Sheet medical examination2
A1: Customer ID | B1: BMI | C1: BMI | D1: Weight status | E1: HBA1C | F1: Diabetic status | G1: Heart Issues | H1: Heart issues | I1: Any Transplants | J1: Cancer history | K1: NumberOfMajorSurgeries | L1: smoker | M1: smoker
A2: Id1 | B2: 47.41 | C2: =ROUND(B2,1) -> 47.4 | D2: {=_xlfn.IFS(C2<18.5,"UNDERWEIGHT",AND(C2>=18.5,C2<=24.9),"NORMAL WEIGHT",AND(C2>=25,C2<=29.9),"OVERWEIGHT",C2>=30,"OBESITY")} -> OBESITY | E2: 7.47 | F2: {=_xlfn.IFS(E2<5.7,"NORMAL",AND(E2>=5.7,E2<=6.49),"PREDIABETES",E2>=6.5,"DIABETES")} -> DIABETES | G2: No | H2: =TRIM(PROPER(G2)) -> No | I2: No | J2: No | K2: No major surgery | L2: yes | M2: =TRIM(PROPER(L2)) -> Yes
A3: Id2 | B3: 30.36 | C3: =ROUND(B3,1) -> 30.4 | D3: {=_xlfn.IFS(C3<18.5,"UNDERWEIGHT",AND(C3>=18.5,C3<=24.9),"NORMAL WEIGHT",AND(C3>=25,C3<=29.9),"OVERWEIGHT",C3>=30,"OBESITY")} -> OBESITY | E3: 5.77 | F3: {=_xlfn.IFS(E3<5.7,"NORMAL",AND(E3>=5.7,E3<=6.49),"PREDIABETES",E3>=6.5,"DIABETES")} -> PREDIABETES | G3: No | H3: =TRIM(PROPER(G3)) -> No | I3: No | J3: No | K3: No major surgery | L3: yes | M3: =TRIM(PROPER(L3)) -> Yes
A4: Id3 | B4: 34.485 | C4: =ROUND(B4,1) -> 34.5 | D4: {=_xlfn.IFS(C4<18.5,"UNDERWEIGHT",AND(C4>=18.5,C4<=24.9),"NORMAL WEIGHT",AND(C4>=25,C4<=29.9),"OVERWEIGHT",C4>=30,"OBESITY")} -> OBESITY | E4: 11.87 | F4: {=_xlfn.IFS(E4<5.7,"NORMAL",AND(E4>=5.7,E4<=6.49),"PREDIABETES",E4>=6.5,"DIABETES")} -> DIABETES | G4: yes | H4: =TRIM(PROPER(G4)) -> Yes | I4: No | J4: No | K4: 2 | L4: yes | M4: =TRIM(PROPER(L4)) -> Yes
A5: Id4 | B5: 38.095 | C5: =ROUND(B5,1) -> 38.1 | D5: {=_xlfn.IFS(C5<18.5,"UNDERWEIGHT",AND(C5>=18.5,C5<=24.9),"NORMAL WEIGHT",AND(C5>=25,C5<=29.9),"OVERWEIGHT",C5>=30,"OBESITY")} -> OBESITY | E5: 6.05 | F5: {=_xlfn.IFS(E5<5.7,"NORMAL",AND(E5>=5.7,E5<=6.49),"PREDIABETES",E5>=6.5,"DIABETES")} -> PREDIABETES | G5: No | H5: =TRIM(PROPER(G5)) -> No | I5: No | J5: No | K5: No major surgery | L5: yes | M5: =TRIM(PROPER(L5)) -> Yes
A6: Id5 | B6: 35.53 | C6: =ROUND(B6,1) -> 35.5 | D6: {=_xlfn.IFS(C6<18.5,"UNDERWEIGHT",AND(C6>=18.5,C6<=24.9),"NORMAL WEIGHT",AND(C6>=25,C6<=29.9),"OVERWEIGHT",C6>=30,"OBESITY")} -> OBESITY | E6: 5.45 | F6: {=_xlfn.IFS(E6<5.7,"NORMAL",AND(E6>=5.7,E6<=6.49),"PREDIABETES",E6>=6.5,"DIABETES")} -> NORMAL | G6: No | H6: =TRIM(PROPER(G6)) -> No | I6: No | J6: No | K6: No major surgery | L6: yes | M6: =TRIM(PROPER(L6)) -> Yes
A7: Id6 | B7: 32.8 | C7: =ROUND(B7,1) -> 32.8 | D7: {=_xlfn.IFS(C7<18.5,"UNDERWEIGHT",AND(C7>=18.5,C7<=24.9),"NORMAL WEIGHT",AND(C7>=25,C7<=29.9),"OVERWEIGHT",C7>=30,"OBESITY")} -> OBESITY | E7: 6.59 | F7: {=_xlfn.IFS(E7<5.7,"NORMAL",AND(E7>=5.7,E7<=6.49),"PREDIABETES",E7>=6.5,"DIABETES")} -> DIABETES | G7: No | H7: =TRIM(PROPER(G7)) -> No | I7: No | J7: No | K7: No major surgery | L7: yes | M7: =TRIM(PROPER(L7)) -> Yes
A8: Id7 | B8: 36.4 | C8: =ROUND(B8,1) -> 36.4 | D8: {=_xlfn.IFS(C8<18.5,"UNDERWEIGHT",AND(C8>=18.5,C8<=24.9),"NORMAL WEIGHT",AND(C8>=25,C8<=29.9),"OVERWEIGHT",C8>=30,"OBESITY")} -> OBESITY | E8: 6.07 | F8: {=_xlfn.IFS(E8<5.7,"NORMAL",AND(E8>=5.7,E8<=6.49),"PREDIABETES",E8>=6.5,"DIABETES")} -> PREDIABETES | G8: No | H8: =TRIM(PROPER(G8)) -> No | I8: No | J8: No | K8: No major surgery | L8: yes | M8: =TRIM(PROPER(L8)) -> Yes
A9: Id8 | B9: 36.96 | C9: =ROUND(B9,1) -> 37 | D9: {=_xlfn.IFS(C9<18.5,"UNDERWEIGHT",AND(C9>=18.5,C9<=24.9),"NORMAL WEIGHT",AND(C9>=25,C9<=29.9),"OVERWEIGHT",C9>=30,"OBESITY")} -> OBESITY | E9: 7.93 | F9: {=_xlfn.IFS(E9<5.7,"NORMAL",AND(E9>=5.7,E9<=6.49),"PREDIABETES",E9>=6.5,"DIABETES")} -> DIABETES | G9: No | H9: =TRIM(PROPER(G9)) -> No | I9: No | J9: No | K9: 3 | L9: yes | M9: =TRIM(PROPER(L9)) -> Yes
A10: Id9 | B10: 41.14 | C10: =ROUND(B10,1) -> 41.1 | D10: {=_xlfn.IFS(C10<18.5,"UNDERWEIGHT",AND(C10>=18.5,C10<=24.9),"NORMAL WEIGHT",AND(C10>=25,C10<=29.9),"OVERWEIGHT",C10>=30,"OBESITY")} -> OBESITY | E10: 9.58 | F10: {=_xlfn.IFS(E10<5.7,"NORMAL",AND(E10>=5.7,E10<=6.49),"PREDIABETES",E10>=6.5,"DIABETES")} -> DIABETES | G10: yes | H10: =TRIM(PROPER(G10)) -> Yes | I10: No | J10: Yes | K10: 1 | L10: yes | M10: =TRIM(PROPER(L10)) -> Yes
A11: Id10 | B11: 38.06 | C11: =ROUND(B11,1) -> 38.1 | D11: {=_xlfn.IFS(C11<18.5,"UNDERWEIGHT",AND(C11>=18.5,C11<=24.9),"NORMAL WEIGHT",AND(C11>=25,C11<=29.9),"OVERWEIGHT",C11>=30,"OBESITY")} -> OBESITY | E11: 10.79 | F11: {=_xlfn.IFS(E11<5.7,"NORMAL",AND(E11>=5.7,E11<=6.49),"PREDIABETES",E11>=6.5,"DIABETES")} -> DIABETES | G11: No | H11: =TRIM(PROPER(G11)) -> No | I11: No | J11: No | K11: No major surgery | L11: yes | M11: =TRIM(PROPER(L11)) -> Yes
A12: Id11 | B12: 37.7 | C12: =ROUND(B12,1) -> 37.7 | D12: {=_xlfn.IFS(C12<18.5,"UNDERWEIGHT",AND(C12>=18.5,C12<=24.9),"NORMAL WEIGHT",AND(C12>=25,C12<=29.9),"OVERWEIGHT",C12>=30,"OBESITY")} -> OBESITY | E12: 5.96 | F12: {=_xlfn.IFS(E12<5.7,"NORMAL",AND(E12>=5.7,E12<=6.49),"PREDIABETES",E12>=6.5,"DIABETES")} -> PREDIABETES | G12: yes | H12: =TRIM(PROPER(G12)) -> Yes | I12: No | J12: No | K12: 2 | L12: yes | M12: =TRIM(PROPER(L12)) -> Yes
A13: Id12 | B13: 42.13 | C13: =ROUND(B13,1) -> 42.1 | D13: {=_xlfn.IFS(C13<18.5,"UNDERWEIGHT",AND(C13>=18.5,C13<=24.9),"NORMAL WEIGHT",AND(C13>=25,C13<=29.9),"OVERWEIGHT",C13>=30,"OBESITY")} -> OBESITY | E13: 11.9 | F13: {=_xlfn.IFS(E13<5.7,"NORMAL",AND(E13>=5.7,E13<=6.49),"PREDIABETES",E13>=6.5,"DIABETES")} -> DIABETES | G13: No | H13: =TRIM(PROPER(G13)) -> No | I13: No | J13: No | K13: No major surgery | L13: yes | M13: =TRIM(PROPER(L13)) -> Yes
A14: Id13 | B14: 40.92 | C14: =ROUND(B14,1) -> 40.9 | D14: {=_xlfn.IFS(C14<18.5,"UNDERWEIGHT",AND(C14>=18.5,C14<=24.9),"NORMAL WEIGHT",AND(C14>=25,C14<=29.9),"OVERWEIGHT",C14>=30,"OBESITY")} -> OBESITY | E14: 8.41 | F14: {=_xlfn.IFS(E14<5.7,"NORMAL",AND(E14>=5.7,E14<=6.49),"PREDIABETES",E14>=6.5,"DIABETES")} -> DIABETES | G14: No | H14: =TRIM(PROPER(G14)) -> No | I14: No | J14: No | K14: No major surgery | L14: yes | M14: =TRIM(PROPER(L14)) -> Yes
A15: Id14 | B15: 40.565 | C15: =ROUND(B15,1) -> 40.6 | D15: {=_xlfn.IFS(C15<18.5,"UNDERWEIGHT",AND(C15>=18.5,C15<=24.9),"NORMAL WEIGHT",AND(C15>=25,C15<=29.9),"OVERWEIGHT",C15>=30,"OBESITY")} -> OBESITY | E15: 7.02 | F15: {=_xlfn.IFS(E15<5.7,"NORMAL",AND(E15>=5.7,E15<=6.49),"PREDIABETES",E15>=6.5,"DIABETES")} -> DIABETES | G15: No | H15: =TRIM(PROPER(G15)) -> No | I15: No | J15: No | K15: No major surgery | L15: yes | M15: =TRIM(PROPER(L15)) -> Yes
A16: Id15 | B16: 36.385 | C16: =ROUND(B16,1) -> 36.4 | D16: {=_xlfn.IFS(C16<18.5,"UNDERWEIGHT",AND(C16>=18.5,C16<=24.9),"NORMAL WEIGHT",AND(C16>=25,C16<=29.9),"OVERWEIGHT",C16>=30,"OBESITY")} -> OBESITY | E16: 7.59 | F16: {=_xlfn.IFS(E16<5.7,"NORMAL",AND(E16>=5.7,E16<=6.49),"PREDIABETES",E16>=6.5,"DIABETES")} -> DIABETES | G16: yes | H16: =TRIM(PROPER(G16)) -> Yes | I16: No | J16: No | K16: 2 | L16: yes | M16: =TRIM(PROPER(L16)) -> Yes
A17: Id16 | B17: 39.9 | C17: =ROUND(B17,1) -> 39.9 | D17: {=_xlfn.IFS(C17<18.5,"UNDERWEIGHT",AND(C17>=18.5,C17<=24.9),"NORMAL WEIGHT",AND(C17>=25,C17<=29.9),"OVERWEIGHT",C17>=30,"OBESITY")} -> OBESITY | E17: 11.32 | F17: {=_xlfn.IFS(E17<5.7,"NORMAL",AND(E17>=5.7,E17<=6.49),"PREDIABETES",E17>=6.5,"DIABETES")} -> DIABETES | G17: No | H17: =TRIM(PROPER(G17)) -> No | I17: No | J17: No | K17: No major surgery | L17: yes | M17: =TRIM(PROPER(L17)) -> Yes
A18: Id17 | B18: 33.8 | C18: =ROUND(B18,1) -> 33.8 | D18: {=_xlfn.IFS(C18<18.5,"UNDERWEIGHT",AND(C18>=18.5,C18<=24.9),"NORMAL WEIGHT",AND(C18>=25,C18<=29.9),"OVERWEIGHT",C18>=30,"OBESITY")} -> OBESITY | E18: 7.67 | F18: {=_xlfn.IFS(E18<5.7,"NORMAL",AND(E18>=5.7,E18<=6.49),"PREDIABETES",E18>=6.5,"DIABETES")} -> DIABETES | G18: No | H18: =TRIM(PROPER(G18)) -> No | I18: No | J18: No | K18: 3 | L18: yes | M18: =TRIM(PROPER(L18)) -> Yes
A19: Id18 | B19: 36.765 | C19: =ROUND(B19,1) -> 36.8 | D19: {=_xlfn.IFS(C19<18.5,"UNDERWEIGHT",AND(C19>=18.5,C19<=24.9),"NORMAL WEIGHT",AND(C19>=25,C19<=29.9),"OVERWEIGHT",C19>=30,"OBESITY")} -> OBESITY | E19: 7.29 | F19: {=_xlfn.IFS(E19<5.7,"NORMAL",AND(E19>=5.7,E19<=6.49),"PREDIABETES",E19>=6.5,"DIABETES")} -> DIABETES | G19: yes | H19: =TRIM(PROPER(G19)) -> Yes | I19: No | J19: Yes | K19: 1 | L19: yes | M19: =TRIM(PROPER(L19)) -> Yes
A20: Id19 | B20: 36.955 | C20: =ROUND(B20,1) -> 37 | D20: {=_xlfn.IFS(C20<18.5,"UNDERWEIGHT",AND(C20>=18.5,C20<=24.9),"NORMAL WEIGHT",AND(C20>=25,C20<=29.9),"OVERWEIGHT",C20>=30,"OBESITY")} -> OBESITY | E20: 4.72 | F20: {=_xlfn.IFS(E20<5.7,"NORMAL",AND(E20>=5.7,E20<=6.49),"PREDIABETES",E20>=6.5,"DIABETES")} -> NORMAL | G20: yes | H20: =TRIM(PROPER(G20)) -> Yes | I20: No | J20: No | K20: 1 | L20: yes | M20: =TRIM(PROPER(L20)) -> Yes
A21: Id20 | B21: 42.9 | C21: =ROUND(B21,1) -> 42.9 | D21: {=_xlfn.IFS(C21<18.5,"UNDERWEIGHT",AND(C21>=18.5,C21<=24.9),"NORMAL WEIGHT",AND(C21>=25,C21<=29.9),"OVERWEIGHT",C21>=30,"OBESITY")} -> OBESITY | E21: 11.41 | F21: {=_xlfn.IFS(E21<5.7,"NORMAL",AND(E21>=5.7,E21<=6.49),"PREDIABETES",E21>=6.5,"DIABETES")} -> DIABETES | G21: No | H21: =TRIM(PROPER(G21)) -> No | I21: No | J21: No | K21: No major surgery | L21: yes | M21: =TRIM(PROPER(L21)) -> Yes
A22: Id21 | B22: 36.3 | C22: =ROUND(B22,1) -> 36.3 | D22: {=_xlfn.IFS(C22<18.5,"UNDERWEIGHT",AND(C22>=18.5,C22<=24.9),"NORMAL WEIGHT",AND(C22>=25,C22<=29.9),"OVERWEIGHT",C22>=30,"OBESITY")} -> OBESITY | E22: 11.5 | F22: {=_xlfn.IFS(E22<5.7,"NORMAL",AND(E22>=5.7,E22<=6.49),"PREDIABETES",E22>=6.5,"DIABETES")} -> DIABETES | G22: yes | H22: =TRIM(PROPER(G22)) -> Yes | I22: No | J22: No | K22: 2 | L22: yes | M22: =TRIM(PROPER(L22)) -> Yes
A23: Id22 | B23: 32.2 | C23: =ROUND(B23,1) -> 32.2 | D23: {=_xlfn.IFS(C23<18.5,"UNDERWEIGHT",AND(C23>=18.5,C23<=24.9),"NORMAL WEIGHT",AND(C23>=25,C23<=29.9),"OVERWEIGHT",C23>=30,"OBESITY")} -> OBESITY | E23: 6.22 | F23: {=_xlfn.IFS(E23<5.7,"NORMAL",AND(E23>=5.7,E23<=6.49),"PREDIABETES",E23>=6.5,"DIABETES")} -> PREDIABETES | G23: yes | H23: =TRIM(PROPER(G23)) -> Yes | I23: No | J23: No | K23: 2 | L23: yes | M23: =TRIM(PROPER(L23)) -> Yes
A24: Id23 | B24: 31.3 | C24: =ROUND(B24,1) -> 31.3 | D24: {=_xlfn.IFS(C24<18.5,"UNDERWEIGHT",AND(C24>=18.5,C24<=24.9),"NORMAL WEIGHT",AND(C24>=25,C24<=29.9),"OVERWEIGHT",C24>=30,"OBESITY")} -> OBESITY | E24: 11.38 | F24: {=_xlfn.IFS(E24<5.7,"NORMAL",AND(E24>=5.7,E24<=6.49),"PREDIABETES",E24>=6.5,"DIABETES")} -> DIABETES | G24: No | H24: =TRIM(PROPER(G24)) -> No | I24: No | J24: No | K24: 3 | L24: yes | M24: =TRIM(PROPER(L24)) -> Yes
A25: Id24 | B25: 41.8 | C25: =ROUND(B25,1) -> 41.8 | D25: {=_xlfn.IFS(C25<18.5,"UNDERWEIGHT",AND(C25>=18.5,C25<=24.9),"NORMAL WEIGHT",AND(C25>=25,C25<=29.9),"OVERWEIGHT",C25>=30,"OBESITY")} -> OBESITY | E25: 7.89 | F25: {=_xlfn.IFS(E25<5.7,"NORMAL",AND(E25>=5.7,E25<=6.49),"PREDIABETES",E25>=6.5,"DIABETES")} -> DIABETES | G25: yes | H25: =TRIM(PROPER(G25)) -> Yes | I25: No | J25: No | K25: 2 | L25: yes | M25: =TRIM(PROPER(L25)) -> Yes
A26: Id25 | B26: 35.09 | C26: =ROUND(B26,1) -> 35.1 | D26: {=_xlfn.IFS(C26<18.5,"UNDERWEIGHT",AND(C26>=18.5,C26<=24.9),"NORMAL WEIGHT",AND(C26>=25,C26<=29.9),"OVERWEIGHT",C26>=30,"OBESITY")} -> OBESITY | E26: 4.38 | F26: {=_xlfn.IFS(E26<5.7,"NORMAL",AND(E26>=5.7,E26<=6.49),"PREDIABETES",E26>=6.5,"DIABETES")} -> NORMAL | G26: yes | H26: =TRIM(PROPER(G26)) -> Yes | I26: No | J26: No | K26: 2 | L26: yes | M26: =TRIM(PROPER(L26)) -> Yes
A27: Id26 | B27: 33.88 | C27: =ROUND(B27,1) -> 33.9 | D27: {=_xlfn.IFS(C27<18.5,"UNDERWEIGHT",AND(C27>=18.5,C27<=24.9),"NORMAL WEIGHT",AND(C27>=25,C27<=29.9),"OVERWEIGHT",C27>=30,"OBESITY")} -> OBESITY | E27: 7.01 | F27: {=_xlfn.IFS(E27<5.7,"NORMAL",AND(E27>=5.7,E27<=6.49),"PREDIABETES",E27>=6.5,"DIABETES")} -> DIABETES | G27: No | H27: =TRIM(PROPER(G27)) -> No | I27: No | J27: No | K27: 3 | L27: yes | M27: =TRIM(PROPER(L27)) -> Yes
A28: Id27 | B28: 30.875 | C28: =ROUND(B28,1) -> 30.9 | D28: {=_xlfn.IFS(C28<18.5,"UNDERWEIGHT",AND(C28>=18.5,C28<=24.9),"NORMAL WEIGHT",AND(C28>=25,C28<=29.9),"OVERWEIGHT",C28>=30,"OBESITY")} -> OBESITY | E28: 11.88 | F28: {=_xlfn.IFS(E28<5.7,"NORMAL",AND(E28>=5.7,E28<=6.49),"PREDIABETES",E28>=6.5,"DIABETES")} -> DIABETES | G28: No | H28: =TRIM(PROPER(G28)) -> No | I28: No | J28: No | K28: No major surgery | L28: yes | M28: =TRIM(PROPER(L28)) -> Yes
A29: Id28 | B29: 36.86 | C29: =ROUND(B29,1) -> 36.9 | D29: {=_xlfn.IFS(C29<18.5,"UNDERWEIGHT",AND(C29>=18.5,C29<=24.9),"NORMAL WEIGHT",AND(C29>=25,C29<=29.9),"OVERWEIGHT",C29>=30,"OBESITY")} -> OBESITY | E29: 5.19 | F29: {=_xlfn.IFS(E29<5.7,"NORMAL",AND(E29>=5.7,E29<=6.49),"PREDIABETES",E29>=6.5,"DIABETES")} -> NORMAL | G29: yes | H29: =TRIM(PROPER(G29)) -> Yes | I29: No | J29: Yes | K29: 1 | L29: yes | M29: =TRIM(PROPER(L29)) -> Yes
A30: Id29 | B30: 35.86 | C30: =ROUND(B30,1) -> 35.9 | D30: {=_xlfn.IFS(C30<18.5,"UNDERWEIGHT",AND(C30>=18.5,C30<=24.9),"NORMAL WEIGHT",AND(C30>=25,C30<=29.9),"OVERWEIGHT",C30>=30,"OBESITY")} -> OBESITY | E30: 6.74 | F30: {=_xlfn.IFS(E30<5.7,"NORMAL",AND(E30>=5.7,E30<=6.49),"PREDIABETES",E30>=6.5,"DIABETES")} -> DIABETES | G30: yes | H30: =TRIM(PROPER(G30)) -> Yes | I30: No | J30: No | K30: 2 | L30: yes | M30: =TRIM(PROPER(L30)) -> Yes
A31: Id30 | B31: 37.05 | C31: =ROUND(B31,1) -> 37.1 | D31: {=_xlfn.IFS(C31<18.5,"UNDERWEIGHT",AND(C31>=18.5,C31<=24.9),"NORMAL WEIGHT",AND(C31>=25,C31<=29.9),"OVERWEIGHT",C31>=30,"OBESITY")} -> OBESITY | E31: 8.44 | F31: {=_xlfn.IFS(E31<5.7,"NORMAL",AND(E31>=5.7,E31<=6.49),"PREDIABETES",E31>=6.5,"DIABETES")} -> DIABETES | G31: No | H31: =TRIM(PROPER(G31)) -> No | I31: No | J31: No | K31: No major surgery | L31: yes | M31: =TRIM(PROPER(L31)) -> Yes
A32: Id31 | B32: 43.89 | C32: =ROUND(B32,1) -> 43.9 | D32: {=_xlfn.IFS(C32<18.5,"UNDERWEIGHT",AND(C32>=18.5,C32<=24.9),"NORMAL WEIGHT",AND(C32>=25,C32<=29.9),"OVERWEIGHT",C32>=30,"OBESITY")} -> OBESITY | E32: 8.71 | F32: {=_xlfn.IFS(E32<5.7,"NORMAL",AND(E32>=5.7,E32<=6.49),"PREDIABETES",E32>=6.5,"DIABETES")} -> DIABETES | G32: No | H32: =TRIM(PROPER(G32)) -> No | I32: No | J32: No | K32: No major surgery | L32: yes | M32: =TRIM(PROPER(L32)) -> Yes
A33: Id32 | B33: 42.35 | C33: =ROUND(B33,1) -> 42.4 | D33: {=_xlfn.IFS(C33<18.5,"UNDERWEIGHT",AND(C33>=18.5,C33<=24.9),"NORMAL WEIGHT",AND(C33>=25,C33<=29.9),"OVERWEIGHT",C33>=30,"OBESITY")} -> OBESITY | E33: 5.08 | F33: {=_xlfn.IFS(E33<5.7,"NORMAL",AND(E33>=5.7,E33<=6.49),"PREDIABETES",E33>=6.5,"DIABETES")} -> NORMAL | G33: yes | H33: =TRIM(PROPER(G33)) -> Yes | I33: No | J33: No | K33: No major surgery | L33: yes | M33: =TRIM(PROPER(L33)) -> Yes
A34: Id33 | B34: 31.35 | C34: =ROUND(B34,1) -> 31.4 | D34: {=_xlfn.IFS(C34<18.5,"UNDERWEIGHT",AND(C34>=18.5,C34<=24.9),"NORMAL WEIGHT",AND(C34>=25,C34<=29.9),"OVERWEIGHT",C34>=30,"OBESITY")} -> OBESITY | E34: 6.86 | F34: {=_xlfn.IFS(E34<5.7,"NORMAL",AND(E34>=5.7,E34<=6.49),"PREDIABETES",E34>=6.5,"DIABETES")} -> DIABETES | G34: No | H34: =TRIM(PROPER(G34)) -> No | I34: No | J34: No | K34: No major surgery | L34: yes | M34: =TRIM(PROPER(L34)) -> Yes
A35: Id34 | B35: 47.6 | C35: =ROUND(B35,1) -> 47.6 | D35: {=_xlfn.IFS(C35<18.5,"UNDERWEIGHT",AND(C35>=18.5,C35<=24.9),"NORMAL WEIGHT",AND(C35>=25,C35<=29.9),"OVERWEIGHT",C35>=30,"OBESITY")} -> OBESITY | E35: 5.95 | F35: {=_xlfn.IFS(E35<5.7,"NORMAL",AND(E35>=5.7,E35<=6.49),"PREDIABETES",E35>=6.5,"DIABETES")} -> PREDIABETES | G35: yes | H35: =TRIM(PROPER(G35)) -> Yes | I35: No | J35: No | K35: No major surgery | L35: yes | M35: =TRIM(PROPER(L35)) -> Yes
A36: Id35 | B36: 46.2 | C36: =ROUND(B36,1) -> 46.2 | D36: {=_xlfn.IFS(C36<18.5,"UNDERWEIGHT",AND(C36>=18.5,C36<=24.9),"NORMAL WEIGHT",AND(C36>=25,C36<=29.9),"OVERWEIGHT",C36>=30,"OBESITY")} -> OBESITY | E36: 6.09 | F36: {=_xlfn.IFS(E36<5.7,"NORMAL",AND(E36>=5.7,E36<=6.49),"PREDIABETES",E36>=6.5,"DIABETES")} -> PREDIABETES | G36: No | H36: =TRIM(PROPER(G36)) -> No | I36: No | J36: Yes | K36: 1 | L36: yes | M36: =TRIM(PROPER(L36)) -> Yes
A37: Id36 | B37: 32.015 | C37: =ROUND(B37,1) -> 32 | D37: {=_xlfn.IFS(C37<18.5,"UNDERWEIGHT",AND(C37>=18.5,C37<=24.9),"NORMAL WEIGHT",AND(C37>=25,C37<=29.9),"OVERWEIGHT",C37>=30,"OBESITY")} -> OBESITY | E37: 11.75 | F37: {=_xlfn.IFS(E37<5.7,"NORMAL",AND(E37>=5.7,E37<=6.49),"PREDIABETES",E37>=6.5,"DIABETES")} -> DIABETES | G37: No | H37: =TRIM(PROPER(G37)) -> No | I37: No | J37: No | K37: No major surgery | L37: yes | M37: =TRIM(PROPER(L37)) -> Yes
A38: Id37 | B38: 40.565 | C38: =ROUND(B38,1) -> 40.6 | D38: {=_xlfn.IFS(C38<18.5,"UNDERWEIGHT",AND(C38>=18.5,C38<=24.9),"NORMAL WEIGHT",AND(C38>=25,C38<=29.9),"OVERWEIGHT",C38>=30,"OBESITY")} -> OBESITY | E38: 7.37 | F38: {=_xlfn.IFS(E38<5.7,"NORMAL",AND(E38>=5.7,E38<=6.49),"PREDIABETES",E38>=6.5,"DIABETES")} -> DIABETES | G38: No | H38: =TRIM(PROPER(G38)) -> No | I38: No | J38: No | K38: No major surgery | L38: yes | M38: =TRIM(PROPER(L38)) -> Yes
A39: Id38 | B39: 32.45 | C39: =ROUND(B39,1) -> 32.5 | D39: {=_xlfn.IFS(C39<18.5,"UNDERWEIGHT",AND(C39>=18.5,C39<=24.9),"NORMAL WEIGHT",AND(C39>=25,C39<=29.9),"OVERWEIGHT",C39>=30,"OBESITY")} -> OBESITY | E39: 11.91 | F39: {=_xlfn.IFS(E39<5.7,"NORMAL",AND(E39>=5.7,E39<=6.49),"PREDIABETES",E39>=6.5,"DIABETES")} -> DIABETES | G39: No | H39: =TRIM(PROPER(G39)) -> No | I39: No | J39: No | K39: No major surgery | L39: yes | M39: =TRIM(PROPER(L39)) -> Yes
A40: Id39 | B40: 34.96 | C40: =ROUND(B40,1) -> 35 | D40: {=_xlfn.IFS(C40<18.5,"UNDERWEIGHT",AND(C40>=18.5,C40<=24.9),"NORMAL WEIGHT",AND(C40>=25,C40<=29.9),"OVERWEIGHT",C40>=30,"OBESITY")} -> OBESITY | E40: 6.52 | F40: {=_xlfn.IFS(E40<5.7,"NORMAL",AND(E40>=5.7,E40<=6.49),"PREDIABETES",E40>=6.5,"DIABETES")} -> DIABETES | G40: No | H40: =TRIM(PROPER(G40)) -> No | I40: No | J40: No | K40: No major surgery | L40: yes | M40: =TRIM(PROPER(L40)) -> Yes
...

Sheet hospitalisation details 2
A1: Customer ID | B1: year | C1: year | D1: month | E1: month filling | F1: date | G1: date of birth | H1: age | I1: children | J1: charges | K1: Hospital tier | L1: hospital tier filling null | M1: City tier | N1: city tier filling null | O1: State ID | P1: state id filling null | S1: data collection date
A2: Id2335 | B2: 1992 | C2: =IF(B2="?",ROUND(AVERAGE(B1:B2344),0),B2) -> 1992 | D2: Jul | E2: =IF(D2="?","sep",D2) -> Jul | F2: 9 | G2: =VALUE(F2&"-"&E2&"-"&C2) -> 33794 | I2: 0 | J2: 563.84 | K2: tier - 2 | L2: {=IF(K2="?",INDEX(K2:K2344,_xlfn.MODE.MULT(MATCH(K2:K2344,K2344,0))),K2)} -> tier - 2 | M2: tier - 3 | N2: {=IF(M2="?",INDEX(M2:M2344,_xlfn.MODE.MULT(MATCH(M2:M2344,M2:M2344,0))),M2)} -> tier - 3 | O2: R1013 | P2: =IF(O2="?","unknown",O2) -> R1013 | S2: 8/072023
A3: Id2334 | B3: 1992 | C3: =IF(B3="?",ROUND(AVERAGE(B2:B2345),0),B3) -> 1992 | D3: Nov | E3: =IF(D3="?","sep",D3) -> Nov | F3: 30 | G3: =VALUE(F3&"-"&E3&"-"&C3) -> 33938 | I3: 0 | J3: 570.62 | K3: tier - 2 | L3: {=IF(K3="?",INDEX(K3:K2345,_xlfn.MODE.MULT(MATCH(K3:K2345,K2345,0))),K3)} -> tier - 2 | M3: tier - 1 | N3: {=IF(M3="?",INDEX(M3:M2345,_xlfn.MODE.MULT(MATCH(M3:M2345,M3:M2345,0))),M3)} -> tier - 1 | O3: R1013 | P3: =IF(O3="?","unknown",O3) -> R1013
A4: Id2333 | B4: 1993 | C4: =IF(B4="?",ROUND(AVERAGE(B3:B2346),0),B4) -> 1993 | D4: Jun | E4: =IF(D4="?","sep",D4) -> Jun | F4: 30 | G4: =VALUE(F4&"-"&E4&"-"&C4) -> 34150 | I4: 0 | J4: 600 | K4: tier - 2 | L4: {=IF(K4="?",INDEX(K4:K2346,_xlfn.MODE.MULT(MATCH(K4:K2346,K2346,0))),K4)} -> tier - 2 | M4: tier - 1 | N4: {=IF(M4="?",INDEX(M4:M2346,_xlfn.MODE.MULT(MATCH(M4:M2346,M4:M2346,0))),M4)} -> tier - 1 | O4: R1013 | P4: =IF(O4="?","unknown",O4) -> R1013
A5: Id2332 | B5: 1992 | C5: =IF(B5="?",ROUND(AVERAGE(B4:B2347),0),B5) -> 1992 | D5: Sep | E5: =IF(D5="?","sep",D5) -> Sep | F5: 13 | G5: =VALUE(F5&"-"&E5&"-"&C5) -> 33860 | I5: 0 | J5: 604.54 | K5: tier - 3 | L5: {=IF(K5="?",INDEX(K5:K2347,_xlfn.MODE.MULT(MATCH(K5:K2347,K2347,0))),K5)} -> tier - 3 | M5: tier - 3 | N5: {=IF(M5="?",INDEX(M5:M2347,_xlfn.MODE.MULT(MATCH(M5:M2347,M5:M2347,0))),M5)} -> tier - 3 | O5: R1013 | P5: =IF(O5="?","unknown",O5) -> R1013
A6: Id2331 | B6: 1998 | C6: =IF(B6="?",ROUND(AVERAGE(B5:B2348),0),B6) -> 1998 | D6: Jul | E6: =IF(D6="?","sep",D6) -> Jul | F6: 27 | G6: =VALUE(F6&"-"&E6&"-"&C6) -> 36003 | I6: 0 | J6: 637.26 | K6: tier - 3 | L6: {=IF(K6="?",INDEX(K6:K2348,_xlfn.MODE.MULT(MATCH(K6:K2348,K2348,0))),K6)} -> tier - 3 | M6: tier - 3 | N6: {=IF(M6="?",INDEX(M6:M2348,_xlfn.MODE.MULT(MATCH(M6:M2348,M6:M2348,0))),M6)} -> tier - 3 | O6: R1013 | P6: =IF(O6="?","unknown",O6) -> R1013
A7: Id2330 | B7: 2001 | C7: =IF(B7="?",ROUND(AVERAGE(B6:B2349),0),B7) -> 2001 | D7: Nov | E7: =IF(D7="?","sep",D7) -> Nov | F7: 20 | G7: =VALUE(F7&"-"&E7&"-"&C7) -> 37215 | I7: 0 | J7: 646.14 | K7: tier - 3 | L7: {=IF(K7="?",INDEX(K7:K2349,_xlfn.MODE.MULT(MATCH(K7:K2349,K2349,0))),K7)} -> tier - 3 | M7: tier - 3 | N7: {=IF(M7="?",INDEX(M7:M2349,_xlfn.MODE.MULT(MATCH(M7:M2349,M7:M2349,0))),M7)} -> tier - 3 | O7: R1012 | P7: =IF(O7="?","unknown",O7) -> R1012
A8: Id2329 | B8: 1993 | C8: =IF(B8="?",ROUND(AVERAGE(B7:B2350),0),B8) -> 1993 | D8: Jun | E8: =IF(D8="?","sep",D8) -> Jun | F8: 1 | G8: =VALUE(F8&"-"&E8&"-"&C8) -> 34121 | I8: 0 | J8: 650 | K8: tier - 3 | L8: {=IF(K8="?",INDEX(K8:K2350,_xlfn.MODE.MULT(MATCH(K8:K2350,K2350,0))),K8)} -> tier - 3 | M8: tier - 3 | N8: {=IF(M8="?",INDEX(M8:M2350,_xlfn.MODE.MULT(MATCH(M8:M2350,M8:M2350,0))),M8)} -> tier - 3 | O8: R1013 | P8: =IF(O8="?","unknown",O8) -> R1013
A9: Id2328 | B9: 1995 | C9: =IF(B9="?",ROUND(AVERAGE(B8:B2351),0),B9) -> 1995 | D9: Jul | E9: =IF(D9="?","sep",D9) -> Jul | F9: 4 | G9: =VALUE(F9&"-"&E9&"-"&C9) -> 34884 | I9: 0 | J9: 650 | K9: tier - 3 | L9: {=IF(K9="?",INDEX(K9:K2351,_xlfn.MODE.MULT(MATCH(K9:K2351,K2351,0))),K9)} -> tier - 3 | M9: tier - 3 | N9: {=IF(M9="?",INDEX(M9:M2351,_xlfn.MODE.MULT(MATCH(M9:M2351,M9:M2351,0))),M9)} -> tier - 3 | O9: R1013 | P9: =IF(O9="?","unknown",O9) -> R1013
A10: Id2327 | B10: 2002 | C10: =IF(B10="?",ROUND(AVERAGE(B9:B2352),0),B10) -> 2002 | D10: Nov | E10: =IF(D10="?","sep",D10) -> Nov | F10: 29 | G10: =VALUE(F10&"-"&E10&"-"&C10) -> 37589 | I10: 0 | J10: 668 | K10: tier - 3 | L10: {=IF(K10="?",INDEX(K10:K2352,_xlfn.MODE.MULT(MATCH(K10:K2352,K2352,0))),K10)} -> tier - 3 | M10: tier - 2 | N10: {=IF(M10="?",INDEX(M10:M2352,_xlfn.MODE.MULT(MATCH(M10:M2352,M10:M2352,0))),M10)} -> tier - 2 | O10: R1012 | P10: =IF(O10="?","unknown",O10) -> R1012
A11: Id2326 | B11: 1997 | C11: =IF(B11="?",ROUND(AVERAGE(B10:B2353),0),B11) -> 1997 | D11: Nov | E11: =IF(D11="?","sep",D11) -> Nov | F11: 9 | G11: =VALUE(F11&"-"&E11&"-"&C11) -> 35743 | I11: 0 | J11: 670 | K11: tier - 3 | L11: {=IF(K11="?",INDEX(K11:K2353,_xlfn.MODE.MULT(MATCH(K11:K2353,K2353,0))),K11)} -> tier - 3 | M11: tier - 3 | N11: {=IF(M11="?",INDEX(M11:M2353,_xlfn.MODE.MULT(MATCH(M11:M2353,M11:M2353,0))),M11)} -> tier - 3 | O11: R1013 | P11: =IF(O11="?","unknown",O11) -> R1013
A12: Id2325 | B12: 2001 | C12: =IF(B12="?",ROUND(AVERAGE(B11:B2354),0),B12) -> 2001 | D12: Sep | E12: =IF(D12="?","sep",D12) -> Sep | F12: 12 | G12: =VALUE(F12&"-"&E12&"-"&C12) -> 37146 | I12: 0 | J12: 687.54 | K12: tier - 3 | L12: {=IF(K12="?",INDEX(K12:K2354,_xlfn.MODE.MULT(MATCH(K12:K2354,K2354,0))),K12)} -> tier - 3 | M12: tier - 2 | N12: {=IF(M12="?",INDEX(M12:M2354,_xlfn.MODE.MULT(MATCH(M12:M2354,M12:M2354,0))),M12)} -> tier - 2 | O12: R1013 | P12: =IF(O12="?","unknown",O12) -> R1013
A13: Id2324 | B13: 1999 | C13: =IF(B13="?",ROUND(AVERAGE(B12:B2355),0),B13) -> 1999 | D13: Dec | E13: =IF(D13="?","sep",D13) -> Dec | F13: 26 | G13: =VALUE(F13&"-"&E13&"-"&C13) -> 36520 | I13: 0 | J13: 700 | K13: ? | L13: {=IF(K13="?",INDEX(K13:K2355,_xlfn.MODE.MULT(MATCH(K13:K2355,K2355,0))),K13)} -> #N/A | M13: tier - 3 | N13: {=IF(M13="?",INDEX(M13:M2355,_xlfn.MODE.MULT(MATCH(M13:M2355,M13:M2355,0))),M13)} -> tier - 3 | O13: R1013 | P13: =IF(O13="?","unknown",O13) -> R1013
A14: Id2323 | B14: 1999 | C14: =IF(B14="?",ROUND(AVERAGE(B13:B2356),0),B14) -> 1999 | D14: Dec | E14: =IF(D14="?","sep",D14) -> Dec | F14: 14 | G14: =VALUE(F14&"-"&E14&"-"&C14) -> 36508 | I14: 0 | J14: 722.99 | K14: tier - 3 | L14: {=IF(K14="?",INDEX(K14:K2356,_xlfn.MODE.MULT(MATCH(K14:K2356,K2356,0))),K14)} -> tier - 3 | M14: tier - 1 | N14: {=IF(M14="?",INDEX(M14:M2356,_xlfn.MODE.MULT(MATCH(M14:M2356,M14:M2356,0))),M14)} -> tier - 1 | O14: R1013 | P14: =IF(O14="?","unknown",O14) -> R1013
... A1050: Id1290 | B1050: 1977 | C1050: =IF(B1050="?",ROUND(AVERAGE(B1049:B3392),0),B1050) -> 1977 | D1050: Jul | E1050: =IF(D1050="?","sep",D1050) -> Jul | F1050: 26 | G1050: =VALUE(F1050&"-"&E1050&"-"&C1050) -> 28332 | I1050: 2 | J1050: 8527.53 | K1050: tier - 2 | L1050: {=IF(K1050="?",INDEX(K1050:K3392,_xlfn.MODE.MULT(MATCH(K1050:K3392,K3392,0))),K1050)} -> tier - 2 | M1050: tier - 2 | N1050: {=IF(M1050="?",INDEX(M1050:M3392,_xlfn.MODE.MULT(MATCH(M1050:M3392,M1050:M3392,0))),M1050)} -> tier - 2 | O1050: R1013 | P1050: =IF(O1050="?","unknown",O1050) -> R1013
A1051: Id1289 | B1051: ? | C1051: =IF(B1051="?",ROUND(AVERAGE(B1050:B3393),0),B1051) -> 1977 | D1051: Jul | E1051: =IF(D1051="?","sep",D1051) -> Jul | F1051: 24 | G1051: =VALUE(F1051&"-"&E1051&"-"&C1051) -> 28330 | I1051: 0 | J1051: 8534.67 | K1051: tier - 2 | L1051: {=IF(K1051="?",INDEX(K1051:K3393,_xlfn.MODE.MULT(MATCH(K1051:K3393,K3393,0))),K1051)} -> tier - 2 | M1051: tier - 3 | N1051: {=IF(M1051="?",INDEX(M1051:M3393,_xlfn.MODE.MULT(MATCH(M1051:M3393,M1051:M3393,0))),M1051)} -> tier - 3 | O1051: R1024 | P1051: =IF(O1051="?","unknown",O1051) -> R1024
A1052: Id1288 | B1052: 1981 | C1052: =IF(B1052="?",ROUND(AVERAGE(B1051:B3394),0),B1052) -> 1981 | D1052: Dec | E1052: =IF(D1052="?","sep",D1052) -> Dec | F1052: 27 | G1052: =VALUE(F1052&"-"&E1052&"-"&C1052) -> 29947 | I1052: 3 | J1052: 8538.29 | K1052: tier - 2 | L1052: {=IF(K1052="?",INDEX(K1052:K3394,_xlfn.MODE.MULT(MATCH(K1052:K3394,K3394,0))),K1052)} -> tier - 2 | M1052: tier - 3 | N1052: {=IF(M1052="?",INDEX(M1052:M3394,_xlfn.MODE.MULT(MATCH(M1052:M3394,M1052:M3394,0))),M1052)} -> tier - 3 | O1052: R1024 | P1052: =IF(O1052="?","unknown",O1052) -> R1024
A1053: Id1287 | B1053: 1975 | C1053: =IF(B1053="?",ROUND(AVERAGE(B1052:B3395),0),B1053) -> 1975 | D1053: Nov | E1053: =IF(D1053="?","sep",D1053) -> Nov | F1053: 6 | G1053: =VALUE(F1053&"-"&E1053&"-"&C1053) -> 27704 | I1053: 1 | J1053: 8539.67 | K1053: tier - 2 | L1053: {=IF(K1053="?",INDEX(K1053:K3395,_xlfn.MODE.MULT(MATCH(K1053:K3395,K3395,0))),K1053)} -> tier - 2 | M1053: tier - 3 | N1053: {=IF(M1053="?",INDEX(M1053:M3395,_xlfn.MODE.MULT(MATCH(M1053:M3395,M1053:M3395,0))),M1053)} -> tier - 3 | O1053: R1011 | P1053: =IF(O1053="?","unknown",O1053) -> R1011
A1054: Id1286 | B1054: ? | C1054: =IF(B1054="?",ROUND(AVERAGE(B1053:B3396),0),B1054) -> 1977 | D1054: Dec | E1054: =IF(D1054="?","sep",D1054) -> Dec | F1054: 12 | G1054: =VALUE(F1054&"-"&E1054&"-"&C1054) -> 28471 | I1054: 1 | J1054: 8547.69 | K1054: tier - 2 | L1054: {=IF(K1054="?",INDEX(K1054:K3396,_xlfn.MODE.MULT(MATCH(K1054:K3396,K3396,0))),K1054)} -> tier - 2 | M1054: tier - 1 | N1054: {=IF(M1054="?",INDEX(M1054:M3396,_xlfn.MODE.MULT(MATCH(M1054:M3396,M1054:M3396,0))),M1054)} -> tier - 1 | O1054: R1013 | P1054: =IF(O1054="?","unknown",O1054) -> R1013
A1055: Id1285 | B1055: 1975 | C1055: =IF(B1055="?",ROUND(AVERAGE(B1054:B3397),0),B1055) -> 1975 | D1055: Aug | E1055: =IF(D1055="?","sep",D1055) -> Aug | F1055: 6 | G1055: =VALUE(F1055&"-"&E1055&"-"&C1055) -> 27612 | I1055: 1 | J1055: 8551.35 | K1055: tier - 2 | L1055: {=IF(K1055="?",INDEX(K1055:K3397,_xlfn.MODE.MULT(MATCH(K1055:K3397,K3397,0))),K1055)} -> tier - 2 | M1055: tier - 2 | N1055: {=IF(M1055="?",INDEX(M1055:M3397,_xlfn.MODE.MULT(MATCH(M1055:M3397,M1055:M3397,0))),M1055)} -> tier - 2 | O1055: R1011 | P1055: =IF(O1055="?","unknown",O1055) -> R1011
A1056: Id1284 | B1056: 1975 | C1056: =IF(B1056="?",ROUND(AVERAGE(B1055:B3398),0),B1056) -> 1975 | D1056: Aug | E1056: =IF(D1056="?","sep",D1056) -> Aug | F1056: 21 | G1056: =VALUE(F1056&"-"&E1056&"-"&C1056) -> 27627 | I1056: 1 | J1056: 8556.91 | K1056: tier - 2 | L1056: {=IF(K1056="?",INDEX(K1056:K3398,_xlfn.MODE.MULT(MATCH(K1056:K3398,K3398,0))),K1056)} -> tier - 2 | M1056: tier - 1 | N1056: {=IF(M1056="?",INDEX(M1056:M3398,_xlfn.MODE.MULT(MATCH(M1056:M3398,M1056:M3398,0))),M1056)} -> tier - 1 | O1056: R1011 | P1056: =IF(O1056="?","unknown",O1056) -> R1011
A1057: Id1283 | B1057: 1988 | C1057: =IF(B1057="?",ROUND(AVERAGE(B1056:B3399),0),B1057) -> 1988 | D1057: Sep | E1057: =IF(D1057="?","sep",D1057) -> Sep | F1057: 21 | G1057: =VALUE(F1057&"-"&E1057&"-"&C1057) -> 32407 | I1057: 3 | J1057: 8567.25 | K1057: tier - 2 | L1057: {=IF(K1057="?",INDEX(K1057:K3399,_xlfn.MODE.MULT(MATCH(K1057:K3399,K3399,0))),K1057)} -> tier - 2 | M1057: tier - 1 | N1057: {=IF(M1057="?",INDEX(M1057:M3399,_xlfn.MODE.MULT(MATCH(M1057:M3399,M1057:M3399,0))),M1057)} -> tier - 1 | O1057: R1012 | P1057: =IF(O1057="?","unknown",O1057) -> R1012
A1058: Id1282 | B1058: 1975 | C1058: =IF(B1058="?",ROUND(AVERAGE(B1057:B3400),0),B1058) -> 1975 | D1058: Sep | E1058: =IF(D1058="?","sep",D1058) -> Sep | F1058: 26 | G1058: =VALUE(F1058&"-"&E1058&"-"&C1058) -> 27663 | I1058: 1 | J1058: 8569.86 | K1058: tier - 2 | L1058: {=IF(K1058="?",INDEX(K1058:K3400,_xlfn.MODE.MULT(MATCH(K1058:K3400,K3400,0))),K1058)} -> tier - 2 | M1058: tier - 3 | N1058: {=IF(M1058="?",INDEX(M1058:M3400,_xlfn.MODE.MULT(MATCH(M1058:M3400,M1058:M3400,0))),M1058)} -> tier - 3 | O1058: R1013 | P1058: =IF(O1058="?","unknown",O1058) -> R1013
A1059: Id1281 | B1059: 1982 | C1059: =IF(B1059="?",ROUND(AVERAGE(B1058:B3401),0),B1059) -> 1982 | D1059: Dec | E1059: =IF(D1059="?","sep",D1059) -> Dec | F1059: 6 | G1059: =VALUE(F1059&"-"&E1059&"-"&C1059) -> 30291 | I1059: 3 | J1059: 8572.04 | K1059: tier - 2 | L1059: {=IF(K1059="?",INDEX(K1059:K3401,_xlfn.MODE.MULT(MATCH(K1059:K3401,K3401,0))),K1059)} -> tier - 2 | M1059: tier - 2 | N1059: {=IF(M1059="?",INDEX(M1059:M3401,_xlfn.MODE.MULT(MATCH(M1059:M3401,M1059:M3401,0))),M1059)} -> tier - 2 | O1059: R1021 | P1059: =IF(O1059="?","unknown",O1059) -> R1021
A1060: Id1280 | B1060: 1987 | C1060: =IF(B1060="?",ROUND(AVERAGE(B1059:B3402),0),B1060) -> 1987 | D1060: Nov | E1060: =IF(D1060="?","sep",D1060) -> Nov | F1060: 11 | G1060: =VALUE(F1060&"-"&E1060&"-"&C1060) -> 32092 | I1060: 3 | J1060: 8573.3 | K1060: tier - 2 | L1060: {=IF(K1060="?",INDEX(K1060:K3402,_xlfn.MODE.MULT(MATCH(K1060:K3402,K3402,0))),K1060)} -> tier - 2 | M1060: tier - 2 | N1060: {=IF(M1060="?",INDEX(M1060:M3402,_xlfn.MODE.MULT(MATCH(M1060:M3402,M1060:M3402,0))),M1060)} -> tier - 2 | O1060: R1021 | P1060: =IF(O1060="?","unknown",O1060) -> R1021
A1061: Id1279 | B1061: 1983 | C1061: =IF(B1061="?",ROUND(AVERAGE(B1060:B3403),0),B1061) -> 1983 | D1061: Dec | E1061: =IF(D1061="?","sep",D1061) -> Dec | F1061: 30 | G1061: =VALUE(F1061&"-"&E1061&"-"&C1061) -> 30680 | I1061: 5 | J1061: 8582.3 | K1061: tier - 2 | L1061: {=IF(K1061="?",INDEX(K1061:K3403,_xlfn.MODE.MULT(MATCH(K1061:K3403,K3403,0))),K1061)} -> tier - 2 | M1061: tier - 1 | N1061: {=IF(M1061="?",INDEX(M1061:M3403,_xlfn.MODE.MULT(MATCH(M1061:M3403,M1061:M3403,0))),M1061)} -> tier - 1 | O1061: R1013 | P1061: =IF(O1061="?","unknown",O1061) -> R1013
A1062: Id1278 | B1062: 1983 | C1062: =IF(B1062="?",ROUND(AVERAGE(B1061:B3404),0),B1062) -> 1983 | D1062: Jul | E1062: =IF(D1062="?","sep",D1062) -> Jul | F1062: 25 | G1062: =VALUE(F1062&"-"&E1062&"-"&C1062) -> 30522 | I1062: 5 | J1062: 8596.83 | K1062: tier - 2 | L1062: {=IF(K1062="?",INDEX(K1062:K3404,_xlfn.MODE.MULT(MATCH(K1062:K3404,K3404,0))),K1062)} -> tier - 2 | M1062: tier - 3 | N1062: {=IF(M1062="?",INDEX(M1062:M3404,_xlfn.MODE.MULT(MATCH(M1062:M3404,M1062:M3404,0))),M1062)} -> tier - 3 | O1062: R1013 | P1062: =IF(O1062="?","unknown",O1062) -> R1013
A1063: Id1277 | B1063: 1973 | C1063: =IF(B1063="?",ROUND(AVERAGE(B1062:B3405),0),B1063) -> 1973 | D1063: Jul | E1063: =IF(D1063="?","sep",D1063) -> Jul | F1063: 11 | G1063: =VALUE(F1063&"-"&E1063&"-"&C1063) -> 26856 | I1063: 0 | J1063: 8601.33 | K1063: tier - 2 | L1063: {=IF(K1063="?",INDEX(K1063:K3405,_xlfn.MODE.MULT(MATCH(K1063:K3405,K3405,0))),K1063)} -> tier - 2 | M1063: tier - 1 | N1063: {=IF(M1063="?",INDEX(M1063:M3405,_xlfn.MODE.MULT(MATCH(M1063:M3405,M1063:M3405,0))),M1063)} -> tier - 1 | O1063: R1013 | P1063: =IF(O1063="?","unknown",O1063) -> R1013
A1064: Id1276 | B1064: 1977 | C1064: =IF(B1064="?",ROUND(AVERAGE(B1063:B3406),0),B1064) -> 1977 | D1064: Sep | E1064: =IF(D1064="?","sep",D1064) -> Sep | F1064: 24 | G1064: =VALUE(F1064&"-"&E1064&"-"&C1064) -> 28392 | I1064: 2 | J1064: 8603.82 | K1064: tier - 2 | L1064: {=IF(K1064="?",INDEX(K1064:K3406,_xlfn.MODE.MULT(MATCH(K1064:K3406,K3406,0))),K1064)} -> tier - 2 | M1064: tier - 1 | N1064: {=IF(M1064="?",INDEX(M1064:M3406,_xlfn.MODE.MULT(MATCH(M1064:M3406,M1064:M3406,0))),M1064)} -> tier - 1 | O1064: R1019 | P1064: =IF(O1064="?","unknown",O1064) -> R1019
A1065: Id1275 | B1065: 1977 | C1065: =IF(B1065="?",ROUND(AVERAGE(B1064:B3407),0),B1065) -> 1977 | D1065: Nov | E1065: =IF(D1065="?","sep",D1065) -> Nov | F1065: 12 | G1065: =VALUE(F1065&"-"&E1065&"-"&C1065) -> 28441 | I1065: 2 | J1065: 8604.48 | K1065: tier - 3 | L1065: {=IF(K1065="?",INDEX(K1065:K3407,_xlfn.MODE.MULT(MATCH(K1065:K3407,K3407,0))),K1065)} -> tier - 3 | M1065: tier - 2 | N1065: {=IF(M1065="?",INDEX(M1065:M3407,_xlfn.MODE.MULT(MATCH(M1065:M3407,M1065:M3407,0))),M1065)} -> tier - 2 | O1065: R1016 | P1065: =IF(O1065="?","unknown",O1065) -> R1016
A1066: Id1274 | B1066: 1977 | C1066: =IF(B1066="?",ROUND(AVERAGE(B1065:B3408),0),B1066) -> 1977 | D1066: Oct | E1066: =IF(D1066="?","sep",D1066) -> Oct | F1066: 15 | G1066: =VALUE(F1066&"-"&E1066&"-"&C1066) -> 28413 | I1066: 3 | J1066: 8605.36 | K1066: tier - 2 | L1066: {=IF(K1066="?",INDEX(K1066:K3408,_xlfn.MODE.MULT(MATCH(K1066:K3408,K3408,0))),K1066)} -> tier - 2 | M1066: tier - 2 | N1066: {=IF(M1066="?",INDEX(M1066:M3408,_xlfn.MODE.MULT(MATCH(M1066:M3408,M1066:M3408,0))),M1066)} -> tier - 2 | O1066: R1013 | P1066: =IF(O1066="?","unknown",O1066) -> R1013
... A2344: Id1 | B2344: 1968 | C2344: =IF(B2344="?",ROUND(AVERAGE(B2343:B4686),0),B2344) -> 1968 | D2344: Oct | E2344: =IF(D2344="?","sep",D2344) -> Oct | F2344: 12 | G2344: =VALUE(F2344&"-"&E2344&"-"&C2344) -> 25123 | I2344: 0 | J2344: 63770.43 | K2344: tier - 1 | L2344: {=IF(K2344="?",INDEX(K2344:K4686,_xlfn.MODE.MULT(MATCH(K2344:K4686,K4686,0))),K2344)} -> tier - 1 | M2344: tier - 3 | N2344: {=IF(M2344="?",INDEX(M2344:M4686,_xlfn.MODE.MULT(MATCH(M2344:M4686,M2344:M4686,0))),M2344)} -> tier - 3 | O2344: R1013 | P2344: =IF(O2344="?","unknown",O2344) -> R1013

Sheet healthcare
A1: Customer ID | B1: first name | C1: BMI | D1: HBA1C | E1: Heart issues | F1: Any Transplans | G1: Cancer history | H1: number of major surgeries | I1: smoker | J1: weight status | K1: diabetic status | L1: date of birth | M1: age | N1: charges
A2: Id1 | B2: =VLOOKUP(A2,'Customer Names'!A2:D2336,4,FALSE) -> Kelly | C2: =VLOOKUP(A2,'medical examination2'!A2:'medical examination2'!B2336,2,FALSE) -> 47.41 | D2: =VLOOKUP(A2,'medical examination2'!A2:E2336,5,FALSE) -> 7.47 | E2: =VLOOKUP(A2,'medical examination2'!A2:G2337,7,FALSE) -> No | F2: =VLOOKUP(healthcare!A2,'medical examination2'!A2:I2336,9,FALSE) -> No | G2: =VLOOKUP(A2,'medical examination2'!A2:J2336,10,FALSE) -> No | I2: =VLOOKUP(A2,'medical examination2'!A2:M2336,13,FALSE) -> Yes | J2: =VLOOKUP(A2,'medical examination2'!A2:D2336,4,FALSE) -> OBESITY | K2: =VLOOKUP(A2,'medical examination2'!A2:F2336,6,FALSE) -> DIABETES | L2: =VLOOKUP(A2,'hospitalisation details 2'!A2:G2344,7,FALSE) -> 25123 | N2: =VLOOKUP(A2,'hospitalisation details 2'!A2:J2344,10,FALSE) -> 63770.43
A3: Id2 | B3: =VLOOKUP(A3,'Customer Names'!A3:D2337,4,FALSE) -> Matthew D | C3: =VLOOKUP(A3,'medical examination2'!A3:'medical examination2'!B2337,2,FALSE) -> 30.36 | D3: =VLOOKUP(A3,'medical examination2'!A3:E2337,5,FALSE) -> 5.77 | E3: =VLOOKUP(A3,'medical examination2'!A3:G2338,7,FALSE) -> No | F3: =VLOOKUP(healthcare!A3,'medical examination2'!A3:I2337,9,FALSE) -> No | G3: =VLOOKUP(A3,'medical examination2'!A3:J2337,10,FALSE) -> No | I3: =VLOOKUP(A3,'medical examination2'!A3:M2337,13,FALSE) -> Yes | J3: =VLOOKUP(A3,'medical examination2'!A3:D2337,4,FALSE) -> OBESITY | K3: =VLOOKUP(A3,'medical examination2'!A3:F2337,6,FALSE) -> PREDIABETES | L3: =VLOOKUP(A3,'hospitalisation details 2'!A3:G2345,7,FALSE) -> 28284 | N3: =VLOOKUP(A3,'hospitalisation details 2'!A3:J2345,10,FALSE) -> 62592.87
A4: Id3 | B4: =VLOOKUP(A4,'Customer Names'!A4:D2338,4,FALSE) -> Phil | C4: =VLOOKUP(A4,'medical examination2'!A4:'medical examination2'!B2338,2,FALSE) -> 34.485 | D4: =VLOOKUP(A4,'medical examination2'!A4:E2338,5,FALSE) -> 11.87 | E4: =VLOOKUP(A4,'medical examination2'!A4:G2339,7,FALSE) -> yes | F4: =VLOOKUP(healthcare!A4,'medical examination2'!A4:I2338,9,FALSE) -> No | G4: =VLOOKUP(A4,'medical examination2'!A4:J2338,10,FALSE) -> No | I4: =VLOOKUP(A4,'medical examination2'!A4:M2338,13,FALSE) -> Yes | J4: =VLOOKUP(A4,'medical examination2'!A4:D2338,4,FALSE) -> OBESITY | K4: =VLOOKUP(A4,'medical examination2'!A4:F2338,6,FALSE) -> DIABETES | L4: =VLOOKUP(A4,'hospitalisation details 2'!A4:G2346,7,FALSE) -> 25822 | N4: =VLOOKUP(A4,'hospitalisation details 2'!A4:J2346,10,FALSE) -> 60021.4
A5: Id4 | B5: =VLOOKUP(A5,'Customer Names'!A5:D2339,4,FALSE) -> Kelsey | C5: =VLOOKUP(A5,'medical examination2'!A5:'medical examination2'!B2339,2,FALSE) -> 38.095 | D5: =VLOOKUP(A5,'medical examination2'!A5:E2339,5,FALSE) -> 6.05 | E5: =VLOOKUP(A5,'medical examination2'!A5:G2340,7,FALSE) -> No | F5: =VLOOKUP(healthcare!A5,'medical examination2'!A5:I2339,9,FALSE) -> No | G5: =VLOOKUP(A5,'medical examination2'!A5:J2339,10,FALSE) -> No | I5: =VLOOKUP(A5,'medical examination2'!A5:M2339,13,FALSE) -> Yes | J5: =VLOOKUP(A5,'medical examination2'!A5:D2339,4,FALSE) -> OBESITY | K5: =VLOOKUP(A5,'medical examination2'!A5:F2339,6,FALSE) -> PREDIABETES | L5: =VLOOKUP(A5,'hospitalisation details 2'!A5:G2347,7,FALSE) -> 33395 | N5: =VLOOKUP(A5,'hospitalisation details 2'!A5:J2347,10,FALSE) -> 58571.07
A6: Id5 | B6: =VLOOKUP(A6,'Customer Names'!A6:D2340,4,FALSE) -> Kristyn | C6: =VLOOKUP(A6,'medical examination2'!A6:'medical examination2'!B2340,2,FALSE) -> 35.53 | D6: =VLOOKUP(A6,'medical examination2'!A6:E2340,5,FALSE) -> 5.45 | E6: =VLOOKUP(A6,'medical examination2'!A6:G2341,7,FALSE) -> No | F6: =VLOOKUP(healthcare!A6,'medical examination2'!A6:I2340,9,FALSE) -> No | G6: =VLOOKUP(A6,'medical examination2'!A6:J2340,10,FALSE) -> No | I6: =VLOOKUP(A6,'medical examination2'!A6:M2340,13,FALSE) -> Yes | J6: =VLOOKUP(A6,'medical examination2'!A6:D2340,4,FALSE) -> OBESITY | K6: =VLOOKUP(A6,'medical examination2'!A6:F2340,6,FALSE) -> NORMAL | L6: =VLOOKUP(A6,'hospitalisation details 2'!A6:G2348,7,FALSE) -> 32678 | N6: =VLOOKUP(A6,'hospitalisation details 2'!A6:J2348,10,FALSE) -> 55135.4
A7: Id6 | B7: =VLOOKUP(A7,'Customer Names'!A7:D2341,4,FALSE) -> Russell B. | C7: =VLOOKUP(A7,'medical examination2'!A7:'medical examination2'!B2341,2,FALSE) -> 32.8 | D7: =VLOOKUP(A7,'medical examination2'!A7:E2341,5,FALSE) -> 6.59 | E7: =VLOOKUP(A7,'medical examination2'!A7:G2342,7,FALSE) -> No | F7: =VLOOKUP(healthcare!A7,'medical examination2'!A7:I2341,9,FALSE) -> No | G7: =VLOOKUP(A7,'medical examination2'!A7:J2341,10,FALSE) -> No | I7: =VLOOKUP(A7,'medical examination2'!A7:M2341,13,FALSE) -> Yes | J7: =VLOOKUP(A7,'medical examination2'!A7:D2341,4,FALSE) -> OBESITY | K7: =VLOOKUP(A7,'medical examination2'!A7:F2341,6,FALSE) -> DIABETES | L7: =VLOOKUP(A7,'hospitalisation details 2'!A7:G2349,7,FALSE) -> 22862 | N7: =VLOOKUP(A7,'hospitalisation details 2'!A7:J2349,10,FALSE) -> 52590.83
A8: Id7 | B8: =VLOOKUP(A8,'Customer Names'!A8:D2342,4,FALSE) -> Scott | C8: =VLOOKUP(A8,'medical examination2'!A8:'medical examination2'!B2342,2,FALSE) -> 36.4 | D8: =VLOOKUP(A8,'medical examination2'!A8:E2342,5,FALSE) -> 6.07 | E8: =VLOOKUP(A8,'medical examination2'!A8:G2343,7,FALSE) -> No | F8: =VLOOKUP(healthcare!A8,'medical examination2'!A8:I2342,9,FALSE) -> No | G8: =VLOOKUP(A8,'medical examination2'!A8:J2342,10,FALSE) -> No | I8: =VLOOKUP(A8,'medical examination2'!A8:M2342,13,FALSE) -> Yes | J8: =VLOOKUP(A8,'medical examination2'!A8:D2342,4,FALSE) -> OBESITY | K8: =VLOOKUP(A8,'medical examination2'!A8:F2342,6,FALSE) -> PREDIABETES | L8: =VLOOKUP(A8,'hospitalisation details 2'!A8:G2350,7,FALSE) -> 34634 | N8: =VLOOKUP(A8,'hospitalisation details 2'!A8:J2350,10,FALSE) -> 51194.56
A9: Id8 | B9: =VLOOKUP(A9,'Customer Names'!A9:D2343,4,FALSE) -> Stephen | C9: =VLOOKUP(A9,'medical examination2'!A9:'medical examination2'!B2343,2,FALSE) -> 36.96 | D9: =VLOOKUP(A9,'medical examination2'!A9:E2343,5,FALSE) -> 7.93 | E9: =VLOOKUP(A9,'medical examination2'!A9:G2344,7,FALSE) -> No | F9: =VLOOKUP(healthcare!A9,'medical examination2'!A9:I2343,9,FALSE) -> No | G9: =VLOOKUP(A9,'medical examination2'!A9:J2343,10,FALSE) -> No | I9: =VLOOKUP(A9,'medical examination2'!A9:M2343,13,FALSE) -> Yes | J9: =VLOOKUP(A9,'medical examination2'!A9:D2343,4,FALSE) -> OBESITY | K9: =VLOOKUP(A9,'medical examination2'!A9:F2343,6,FALSE) -> DIABETES | L9: =VLOOKUP(A9,'hospitalisation details 2'!A9:G2351,7,FALSE) -> 21363 | N9: =VLOOKUP(A9,'hospitalisation details 2'!A9:J2351,10,FALSE) -> 49577.66
A10: Id9 | B10: =VLOOKUP(A10,'Customer Names'!A10:D2344,4,FALSE) -> Patrick R. | C10: =VLOOKUP(A10,'medical examination2'!A10:'medical examination2'!B2344,2,FALSE) -> 41.14 | D10: =VLOOKUP(A10,'medical examination2'!A10:E2344,5,FALSE) -> 9.58 | E10: =VLOOKUP(A10,'medical examination2'!A10:G2345,7,FALSE) -> yes | F10: =VLOOKUP(healthcare!A10,'medical examination2'!A10:I2344,9,FALSE) -> No | G10: =VLOOKUP(A10,'medical examination2'!A10:J2344,10,FALSE) -> Yes | I10: =VLOOKUP(A10,'medical examination2'!A10:M2344,13,FALSE) -> Yes | J10: =VLOOKUP(A10,'medical examination2'!A10:D2344,4,FALSE) -> OBESITY | K10: =VLOOKUP(A10,'medical examination2'!A10:F2344,6,FALSE) -> DIABETES | L10: =VLOOKUP(A10,'hospitalisation details 2'!A10:G2352,7,FALSE) -> 23258 | N10: =VLOOKUP(A10,'hospitalisation details 2'!A10:J2352,10,FALSE) -> 48970.25
A11: Id10 | B11: =VLOOKUP(A11,'Customer Names'!A11:D2345,4,FALSE) -> Brooke N. | C11: =VLOOKUP(A11,'medical examination2'!A11:'medical examination2'!B2345,2,FALSE) -> 38.06 | D11: =VLOOKUP(A11,'medical examination2'!A11:E2345,5,FALSE) -> 10.79 | E11: =VLOOKUP(A11,'medical examination2'!A11:G2346,7,FALSE) -> No | F11: =VLOOKUP(healthcare!A11,'medical examination2'!A11:I2345,9,FALSE) -> No | G11: =VLOOKUP(A11,'medical examination2'!A11:J2345,10,FALSE) -> No | I11: =VLOOKUP(A11,'medical examination2'!A11:M2345,13,FALSE) -> Yes | J11: =VLOOKUP(A11,'medical examination2'!A11:D2345,4,FALSE) -> OBESITY | K11: =VLOOKUP(A11,'medical examination2'!A11:F2345,6,FALSE) -> DIABETES | L11: =VLOOKUP(A11,'hospitalisation details 2'!A11:G2353,7,FALSE) -> 28853 | N11: =VLOOKUP(A11,'hospitalisation details 2'!A11:J2353,10,FALSE) -> 48885.14
A12: Id11 | B12: =VLOOKUP(A12,'Customer Names'!A12:D2346,4,FALSE) -> Paola Andrea | C12: =VLOOKUP(A12,'medical examination2'!A12:'medical examination2'!B2346,2,FALSE) -> 37.7 | D12: =VLOOKUP(A12,'medical examination2'!A12:E2346,5,FALSE) -> 5.96 | E12: =VLOOKUP(A12,'medical examination2'!A12:G2347,7,FALSE) -> yes | F12: =VLOOKUP(healthcare!A12,'medical examination2'!A12:I2346,9,FALSE) -> No | G12: =VLOOKUP(A12,'medical examination2'!A12:J2346,10,FALSE) -> No | I12: =VLOOKUP(A12,'medical examination2'!A12:M2346,13,FALSE) -> Yes | J12: =VLOOKUP(A12,'medical examination2'!A12:D2346,4,FALSE) -> OBESITY | K12: =VLOOKUP(A12,'medical examination2'!A12:F2346,6,FALSE) -> PREDIABETES | L12: =VLOOKUP(A12,'hospitalisation details 2'!A12:G2354,7,FALSE) -> 21753 | N12: =VLOOKUP(A12,'hospitalisation details 2'!A12:J2354,10,FALSE) -> 48824.45
A13: Id12 | B13: =VLOOKUP(A13,'Customer Names'!A13:D2347,4,FALSE) -> David | C13: =VLOOKUP(A13,'medical examination2'!A13:'medical examination2'!B2347,2,FALSE) -> 42.13 | D13: =VLOOKUP(A13,'medical examination2'!A13:E2347,5,FALSE) -> 11.9 | E13: =VLOOKUP(A13,'medical examination2'!A13:G2348,7,FALSE) -> No | F13: =VLOOKUP(healthcare!A13,'medical examination2'!A13:I2347,9,FALSE) -> No | G13: =VLOOKUP(A13,'medical examination2'!A13:J2347,10,FALSE) -> No | I13: =VLOOKUP(A13,'medical examination2'!A13:M2347,13,FALSE) -> Yes | J13: =VLOOKUP(A13,'medical examination2'!A13:D2347,4,FALSE) -> OBESITY | K13: =VLOOKUP(A13,'medical examination2'!A13:F2347,6,FALSE) -> DIABETES | L13: =VLOOKUP(A13,'hospitalisation details 2'!A13:G2355,7,FALSE) -> 24042 | N13: =VLOOKUP(A13,'hospitalisation details 2'!A13:J2355,10,FALSE) -> 48675.52
... A2336: Id2335 | B2336: =VLOOKUP(A2336,'Customer Names'!A2336:D4670,4,FALSE) -> Aaron K | C2336: =VLOOKUP(A2336,'medical examination2'!A2336:'medical examination2'!B4670,2,FALSE) -> 17.58 | D2336: =VLOOKUP(A2336,'medical examination2'!A2336:E4670,5,FALSE) -> 4.51 | E2336: =VLOOKUP(A2336,'medical examination2'!A2336:G4671,7,FALSE) -> No | F2336: =VLOOKUP(healthcare!A2336,'medical examination2'!A2336:I4670,9,FALSE) -> No | G2336: =VLOOKUP(A2336,'medical examination2'!A2336:J4670,10,FALSE) -> No | I2336: =VLOOKUP(A2336,'medical examination2'!A2336:M4670,13,FALSE) -> No | J2336: =VLOOKUP(A2336,'medical examination2'!A2336:D4670,4,FALSE) -> UNDERWEIGHT | K2336: =VLOOKUP(A2336,'medical examination2'!A2336:F4670,6,FALSE) -> NORMAL | L2336: =VLOOKUP(A2336,'hospitalisation details 2'!A2336:G4678,7,FALSE) -> #N/A | N2336: =VLOOKUP(A2336,'hospitalisation details 2'!A2336:J4678,10,FALSE) -> #N/A

Sheet pie chart
